Workbook

Sheet Start Here
A1: Second Responder | Evaluation workbook
A2: 20 starter cases across 12 runbooks. No chatbot answers or scores are pre-filled. Blue text = editable input; gray cells = formulas.
B5: 1 Review the test cases
B6: Open Test Cases. Confirm the expected behavior with the runbook owner before testing. All starter cases are Development; add representative unseen Held-out cases for final assessment.
B8: 2 Run a question in n8n
B9: Use the existing chat workflow. In Responses, use its pre-filled Run ID and Test ID, paste Format Evidence output into Retrieved evidence, and paste the actual LLM answer into Answer.
B11: 3 Record the outcome
B12: Choose Answered, Clarification, Abstained, or Error. Set Response appropriate? by comparing with the expected behavior: useful and sufficient for answerable cases, or a justified clarification/abstention for unsupported cases.
B14: 4 Review every atomic claim
B15: In Claim Review, add one row per factual claim, using the matching Run ID. Separate commands, conditions, thresholds, and escalation rules. Keep an action connected to its prerequisite. Paste the exact supporting excerpt from the evidence actually retrieved for this run.
B17: 5 Complete the verdicts
B18: Faithfulness verdict: Supported, Unsupported, or Contradicted. Citation verdict: Supported, Wrong citation, or Missing citation. A claim can be supported somewhere in context but have a wrong citation. Set Critical error? to Yes for an unsupported command, remediation condition, or escalation threshold. Enter your reviewer name.
B20: 6 Confirm coverage of the answer
B21: In Responses, set Claim inventory complete? to Yes only after checking that every factual claim was listed. Mark this even for a genuine zero-claim clarification. Enter the response reviewer. Incomplete reviews receive no score.
... B44: Evaluation best practices

Sheet Dashboard
A1: Evaluation dashboard | Evidence before confidence
A2: Mean faithfulness uses completely reviewed responses with claims. No answers have been scored yet. Results describe recorded tests, not guaranteed production performance.
A5: Faithfulness target (editable) | B5: 0.9
A7: Scored responses | B7: =COUNT(Responses!$R$6:$R$205) -> 0
A8: Mean faithfulness | B8: =IF(COUNT(Responses!$R$6:$R$205)=0,"Not scored",AVERAGE(Responses!$R$6:$R$205)) -> Not scored
A9: Mean target reached? | B9: =IF(COUNT(Responses!$R$6:$R$205)=0,"Not evaluated",IF(AVERAGE(Responses!$R$6:$R$205)>=B5,"Yes","No")) -> Not evaluated
A10: PASS responses | B10: =COUNTIF(Responses!$S$6:$S$205,"PASS") -> 0
A11: FAIL responses | B11: =COUNTIF(Responses!$S$6:$S$205,"FAIL") -> 0
A12: Citation errors flagged | B12: =SUM(Responses!$M$6:$M$205) -> 0
A13: Critical operational errors flagged | B13: =SUM(Responses!$N$6:$N$205) -> 0
A14: Answered outcomes | B14: =COUNTIF(Responses!$K$6:$K$205,"Answered") -> 0
A15: Clarification / abstention outcomes | B15: =COUNTIF(Responses!$K$6:$K$205,"Clarification")+COUNTIF(Responses!$K$6:$K$205,"Abstained") -> 0
A16: Inappropriate responses flagged | B16: =COUNTIF(Responses!$L$6:$L$205,"No") -> 0
A17: Claims awaiting review | B17: =SUM(Responses!$Q$6:$Q$205) -> 0
A18: Held-out scored responses | B18: =SUMPRODUCT(--(Responses!$C$6:$C$205="Held-out"),--ISNUMBER(Responses!$R$6:$R$205)) -> 0
A19: Held-out mean faithfulness | B19: =IF(B18=0,"Not scored",SUMIF(Responses!$C$6:$C$205,"Held-out",Responses!$R$6:$R$205)/B18) -> Not scored
A20: Answered responses marked appropriate | B20: =COUNTIFS(Responses!$K$6:$K$205,"Answered",Responses!$L$6:$L$205,"Yes",Responses!$B$6:$B$205,"<>") -> 0
A23: A mean of 90% does not make an unsupported command acceptable. Review critical errors separately. Zero observed errors is evidence from these tests, not a guarantee. Examine individual cases and service-level failures; report appropriateness and abstention alongside faithfulness.
A27: All starter tests are Development and no answers are pre-scored. Add unseen Held-out cases. Use unique Run IDs for retests and compare one prompt/model/corpus version at a time. This dashboard aggregates all rows, including repeated runs.

Sheet Test Cases
A1: Test cases | Define expected behavior first
A2: Starter expectations are drawn from local runbook snapshots. All 20 cases are Development. Add unseen cases and label them Held-out before final assessment.
A5: Test ID | B5: Split | C5: Category | D5: Service | E5: Question | F5: Expected outcome | G5: Expected runbooks | H5: Expected key points / source wording | I5: Source URL | J5: Reviewer notes
A6: T001 | B6: Development | C6: Baseline | D6: payments-api | E6: payments-api /charge returns 5xx errors and Stripe requests time out. What should I check, what conditional remediation applies, and when should I escalate? | F6: Answered | G6: RB-001 | H6: **Service:** payments-api | **Owner:** payments team | **Typical severity:** SEV2 (SEV1 if >50% of charges failing) ## Symptoms - Alert: "payments-api 5xx rate above 5% for 5 minutes" - Logs show "502 upstream prematurely closed connection" and "stripe request timeout after 3000ms" - Checkout failures rise in proportion to the error rate ## First checks 1. `kubectl rollout status deploy/payments-api -n prod` and `kubectl get pods -n prod -l app=payments-api` 2. Was there a deploy in the last 30 minutes? Check the deploy feed first. 3. Check status.stripe.com for an active Stripe incident. 4. Look at the orders DB connection pool (see RB-009 if saturated). ## Diagnosis - Errors started within 10 minutes of a deploy: assume bad release until proven otherwise. - Only /charge failing and Stripe status degraded: downstream provider issue, not us. - 503s with "no healthy upstream": connection pool or target pod problem. ## Remediation 1. Bad deploy: `kubectl rollout undo deploy/payments-api -n prod` 2. Stripe degraded: enable queued-charge mode (`payments.queue_mode=true`) so charges retry asynchronously instead of failing at checkout. 3. Pool saturation: follow RB-009. ## Escalation Escalate to the payments on-call lead if the error rate is above 20% or not resolved within 15 minutes. Declare SEV1 if more than 50% of charges are failing. ## After resolution Confirm the error rate stays below 0.5% for 15 minutes before closing the incident. | I6: https://github.com/mahesh-ai-architect/Second-Responder/blob/main/runbooks/RB-001-payments-api-5xx.md | J6: Engineer should verify service relevance, conditions, and required steps. Add RB-009 to expected sources if detailed pool remediation is requested across runbooks.
A7: T002 | B7: Development | C7: Baseline | D7: payments-api | E7: The webhooks-inbound queue is above 10,000 and rising, with delivery failures going to the DLQ. What should I check, how should I recover, and when should I escalate? | F7: Answered | G7: RB-002 | H7: **Service:** payments-api | **Owner:** payments team | **Typical severity:** SEV3 (SEV2 if backlog > 50,000) ## Symptoms - Queue "webhooks-inbound" depth above 10,000 and rising - Consumer lag growing; downstream order and inventory states go stale - Logs show "delivery attempt 8 failed, moving to DLQ" ## First checks 1. `kubectl get pods -n prod -l app=webhook-consumer` - look for CrashLoopBackOff 2. Check whether the same message_id is stuck at the head of the queue (poison message) 3. Check the downstream endpoint's own error rate ## Diagnosis - Consumer crash-looping: usually a bad deploy or a config change. - One message retried forever: poison message blocking the partition. - Downstream endpoint returning 500s: fix the downstream service first, not the consumer. ## Remediation 1. Fix or roll back the consumer deploy. 2. Move the poison message to the DLQ manually, note its message_id in the incident timeline. 3. Scale consumers: `kubectl scale deploy/webhook-consumer -n prod --replicas=6` 4. Replay the DLQ only after the root cause is fixed. Webhook handlers are idempotent on event_id - verify the consumer checks event_id before replaying. ## Escalation SEV2 if the backlog exceeds 50,000 or customer-visible order states are wrong. | I7: https://github.com/mahesh-ai-architect/Second-Responder/blob/main/runbooks/RB-002-payments-api-webhook-backlog.md | J7: Engineer should verify service relevance, conditions, and required steps. Add RB-009 to expected sources if detailed pool remediation is requested across runbooks.
A8: T003 | B8: Development | C8: Baseline | D8: auth-service | E8: SSO login success is below 90%, with SAML signature validation failures. What should I check, what remediation applies, and when should I escalate? | F8: Answered | G8: RB-003 | H8: **Service:** auth-service | **Owner:** identity team | **Typical severity:** SEV1 if all SSO logins fail ## Symptoms - Login success rate below 90% - Errors: "SAML signature validation failed" and "OIDC discovery document fetch failed" ## First checks 1. Fetch the IdP discovery document: `curl https://idp.example.com/.well-known/openid-configuration` 2. Compare the IdP signing certificate fingerprint against the configured metadata. 3. Check node clock drift: `chronyc tracking` - drift above 30 seconds breaks token validation. ## Diagnosis - Most common cause: the IdP rotated its signing certificate and our cached metadata is stale. - Discovery fetch failing: IdP outage or a network/DNS change on our side. - Signature failures plus clock drift: fix NTP before touching metadata. ## Remediation 1. Refresh IdP metadata from the admin console: Identity Providers -> Reload metadata. 2. Clear cached keys: `kubectl rollout restart deploy/auth-service -n prod` 3. If the IdP is down, post the status page notice and wait - do not bypass signature checks. ## Escalation SEV1 if all SSO logins are failing (workforce lockout). Page the identity on-call lead immediately. | I8: https://github.com/mahesh-ai-architect/Second-Responder/blob/main/runbooks/RB-003-auth-service-sso-failures.md | J8: Engineer should verify service relevance, conditions, and required steps. Add RB-009 to expected sources if detailed pool remediation is requested across runbooks.
A9: T004 | B9: Development | C9: Baseline | D9: auth-service | E9: Users are not receiving MFA push prompts and approval latency exceeds 60 seconds. What should I check, what workaround applies, and when should I escalate? | F9: Answered | G9: RB-004 | H9: **Service:** auth-service | **Owner:** identity team | **Typical severity:** SEV3 (SEV2 if >30 minutes) ## Symptoms - Push approval latency above 60 seconds, or failures with "push token revoked" - Users report not receiving MFA prompts ## First checks 1. Check the push vendor status page (APNs/FCM relay provider). 2. Token revocation rate split by platform: iOS vs Android. 3. Confirm TOTP (authenticator app) logins are unaffected. ## Diagnosis - One platform only: platform gateway or vendor-side issue. - Both platforms: our notification service or vendor account throttling. ## Remediation 1. Advise users to fall back to authenticator app (TOTP) codes - use the comms template in the incident channel. 2. If single-platform, open a vendor ticket with sample device tokens and timestamps. 3. Never disable or weaken MFA to "fix" delivery problems. ## Escalation Identity lead plus a vendor P1 ticket if degradation lasts more than 30 minutes or blocks a SEV1/SEV2 response. | I9: https://github.com/mahesh-ai-architect/Second-Responder/blob/main/runbooks/RB-004-auth-service-mfa-push.md | J9: Engineer should verify service relevance, conditions, and required steps. Add RB-009 to expected sources if detailed pool remediation is requested across runbooks.
A10: T005 | B10: Development | C10: Baseline | D10: search | E10: The indexer-nightly job is stalled and logs show mapper_parsing_exception. What should I check, how should I recover, and when should I escalate? | F10: Answered | G10: RB-005 | H10: **Service:** search | **Owner:** platform team | **Typical severity:** SEV3 (SEV2 if customer-facing results stale > 2 hours) ## Symptoms - Nightly job "indexer-nightly" stuck, shard progress frozen - Error "mapper_parsing_exception" in indexer logs, or a data node above 85% disk ## First checks 1. Disk usage per data node; indexing halts at the high watermark. 2. Indexer logs for "mapper_parsing_exception" - a field arrived with a conflicting type. 3. GC pause times on data nodes. ## Diagnosis - Disk above watermark: snapshots or old indices consuming space. - Mapping exception: a producer started sending a field with a new type. - Progress frozen with healthy disk: long GC or a hung shard task. ## Remediation 1. Delete snapshots beyond retention; delete closed indices older than 90 days. 2. Fix the mapping for the offending field, or route that field to a quarantine index. 3. Resume the job from its checkpoint: `indexer-nightly --resume-from-shard` 4. If users also report worse results, check the last search deploy for analyzer changes before blaming the index. ## Escalation Platform on-call lead if customer-facing search results are stale for more than 2 hours. | I10: https://github.com/mahesh-ai-architect/Second-Responder/blob/main/runbooks/RB-005-search-index-rebuild.md | J10: Engineer should verify service relevance, conditions, and required steps. Add RB-009 to expected sources if detailed pool remediation is requested across runbooks.
A11: T006 | B11: Development | C11: Baseline | D11: checkout | E11: Checkout p99 is above 2.5 seconds after a deploy and promo validation dominates traces. What should I check, what remediation applies, and how should I verify recovery? | F11: Answered | G11: RB-006 | H11: **Service:** checkout | **Owner:** growth team | **Typical severity:** SEV2 if conversion impact confirmed ## Symptoms - Checkout p99 latency above 2.5s against a 900ms baseline - APM traces show time concentrated in promo validation or the inventory call ## First checks 1. APM waterfall for a slow trace: which span eats the time? 2. Was "checkout_v2" enabled in the last deploy? 3. Check for N+1 query patterns in cart service database calls. ## Diagnosis - Promo validation called synchronously per cart item: known regression pattern from the v2 flag. - Cache bypass header set by the new frontend build: every request hits origin services. - DB time dominant: hand off to RB-009. ## Remediation 1. Disable the flag: `checkout_v2=false` - instant rollback, no deploy needed. 2. Enable async promo validation: `promo.async_validation=true` 3. Verify p99 below 1.2s for 10 minutes before closing. ## Escalation Growth team lead. SEV2 if analytics confirms a conversion drop. | I11: https://github.com/mahesh-ai-architect/Second-Responder/blob/main/runbooks/RB-006-checkout-latency.md | J11: Engineer should verify service relevance, conditions, and required steps. Add RB-009 to expected sources if detailed pool remediation is requested across runbooks.
A12: T007 | B12: Development | C12: Baseline | D12: notifications | E12: Email queues are backing up and the provider returns 429 provider rate limit exceeded. What should I check, what remediation applies, and when should I escalate? | F12: Answered | G12: RB-007 | H12: **Service:** notifications | **Owner:** platform team | **Typical severity:** SEV3 (SEV2 if OTP/password-reset mail delayed > 15 min) ## Symptoms - Email queue depth rising, send latency above 10 minutes - Provider returns "429 provider rate limit exceeded" ## First checks 1. Split queue depth: transactional vs marketing. A campaign burst sharing the queue is the usual cause. 2. Worker replica count vs the autoscaling cap. 3. Provider rate limit status for our account. ## Diagnosis - Marketing burst: a campaign send flooded the shared queue. - Workers at cap with steady traffic: genuine capacity ceiling. - 429s at low volume: provider-side throttling or account limit change. ## Remediation 1. Prioritize the "notifications-transactional" queue - OTP and password resets go first. 2. Raise worker replicas up to the max of 20. 3. Pause campaign sends: `campaigns.paused=true` 4. Never drop transactional messages to clear a backlog. ## Escalation If password-reset or OTP mail is delayed more than 15 minutes this becomes auth-impacting - raise to SEV2 and cross-reference RB-004. | I12: https://github.com/mahesh-ai-architect/Second-Responder/blob/main/runbooks/RB-007-notifications-queue-backlog.md | J12: Engineer should verify service relevance, conditions, and required steps. Add RB-009 to expected sources if detailed pool remediation is requested across runbooks.
A13: T008 | B13: Development | C13: Baseline | D13: database-primary | E13: Replica lag is above 30 seconds and climbing while a backfill runs. What should I check, what remediation conditions apply, and when should I escalate? | F13: Answered | G13: RB-008 | H13: **Service:** database-primary | **Owner:** platform (DB) team | **Typical severity:** SEV2 (SEV1 if lag > 300s with unhealthy primary) ## Symptoms - Replica lag above 30 seconds and climbing in pg_stat_replication - Read-your-write complaints from application teams ## First checks 1. `SELECT pid, application_name, now() - xact_start AS xact_age FROM pg_stat_activity ORDER BY xact_age DESC;` 2. Identify bulk jobs by application_name - backfills are the usual blocker. 3. Replica disk I/O utilisation. ## Diagnosis - One long transaction on the primary: replica replay is blocked behind it. - Backfill job running during peak: contention, not failure. - Replica disk saturated: replay cannot keep up even with a healthy primary. ## Remediation 1. With incident commander approval, terminate the blocking backfill: `SELECT pg_terminate_backend(<pid>);` 2. Throttle or pause batch jobs until lag drains below 5 seconds. 3. Controlled failover only if the primary is genuinely failing AND lag is under 10 seconds. 4. Never promote a replica with lag above 300 seconds without data-loss sign-off from the DB lead. ## Escalation SEV1 if lag exceeds 300 seconds with an unhealthy primary. Page the DB lead. | I13: https://github.com/mahesh-ai-architect/Second-Responder/blob/main/runbooks/RB-008-database-replication-lag.md | J13: Engineer should verify service relevance, conditions, and required steps. Add RB-009 to expected sources if detailed pool remediation is requested across runbooks.
A14: T009 | B14: Development | C14: Baseline | D14: database-primary | E14: The orders database connection pool is saturated and requests are failing. What should I check first, what remediation should I follow, and when should I escalate? | F14: Answered | G14: RB-009 | H14: **Service:** database-primary | **Owner:** platform (DB) team | **Typical severity:** SEV2 ## Symptoms - Application errors: "FATAL: remaining connection slots are reserved for non-replication superuser connections" - PgBouncer client wait queue growing ## First checks 1. `SELECT application_name, state, count(*) FROM pg_stat_activity GROUP BY 1, 2 ORDER BY 3 DESC;` 2. PgBouncer: `SHOW POOLS;` - look at cl_waiting. 3. Sessions stuck in "idle in transaction" point at a leaking deploy. ## Diagnosis - One application_name dominating with idle-in-transaction sessions: connection leak in a recent deploy. - All apps up evenly: genuine load growth or a batch job. - Pooler queue up but DB sessions low: pool size misconfigured after a deploy. ## Remediation 1. Restart the pooler to clear leaked sessions: `systemctl restart pgbouncer` 2. Roll back the leaking deploy; the leak, not the pool size, is the bug. 3. Temporary pool_size increase of 25% is allowed only if DB CPU is below 60%. ## Escalation DB lead if it recurs twice in 24 hours - that is a leak hunt, treat as SEV2. | I14: https://github.com/mahesh-ai-architect/Second-Responder/blob/main/runbooks/RB-009-database-connection-pool.md | J14: Engineer should verify service relevance, conditions, and required steps. Add RB-009 to expected sources if detailed pool remediation is requested across runbooks.
A15: T010 | B15: Development | C15: Baseline | D15: cdn-edge | E15: CDN cache hit ratio dropped below 70%, origin traffic tripled, and edge 503s appeared after a config push. What should I check and do? | F15: Answered | G15: RB-010 | H15: **Service:** cdn-edge | **Owner:** platform team | **Typical severity:** SEV2 if origin is saturating ## Symptoms - Cache hit ratio below 70% against a 92% baseline - Origin traffic roughly 3x normal; scattered 503s by POP after a config push ## First checks 1. Hit ratio split by POP and by path - global or localized? 2. Was there a CDN config push or a full purge in the last hour? 3. Origin response codes and origin CPU. ## Diagnosis - Cache key changed to include the session cookie: every user becomes a unique cache entry. - Full purge during peak: self-inflicted origin stampede. - One POP only: bad config version on that POP or an origin shield misroute. ## Remediation 1. Roll back the CDN config to the previous known-good version. 2. Enable origin shield and request coalescing to protect the origin. 3. Re-warm the top 500 URLs after rollback. 4. Disable scheduled purges until the root cause is confirmed. ## Escalation SEV2 if the origin is saturating. Protect the origin first, investigate second. | I15: https://github.com/mahesh-ai-architect/Second-Responder/blob/main/runbooks/RB-010-cdn-edge-503.md | J15: Engineer should verify service relevance, conditions, and required steps. Add RB-009 to expected sources if detailed pool remediation is requested across runbooks.
A16: T011 | B16: Development | C16: Baseline | D16: inventory | E16: Stock sync is failing with deadlock detected on sku_locks and oversell alerts are active. What should I check, how should I recover, and who should I notify? | F16: Answered | G16: RB-011 | H16: **Service:** inventory | **Owner:** growth team | **Typical severity:** SEV2 while oversell is active ## Symptoms - Stock sync job failing; oversell alerts on high-velocity SKUs - Errors: "deadlock detected on sku_locks", or the feed file is missing the column "warehouse_id" ## First checks 1. Is more than one sync run executing at once? Overlapping runs deadlock each other. 2. Diff the latest warehouse feed file against the expected schema. 3. Check whether the batch repricing job is running concurrently. ## Diagnosis - Missing "warehouse_id" column: the warehouse changed the feed schema without notice. - Deadlocks with overlapping runs: scheduling collision, not bad data. - Deadlocks with repricing: lock ordering conflict between the two jobs. ## Remediation 1. Stop extra sync runs; rerun a single sync in idempotent reconcile mode: `stock-sync --mode=reconcile` 2. Reconcile counts for affected SKUs from the latest warehouse snapshot. 3. For oversold orders, follow the customer outreach macro - do not hand-edit stock counts outside reconcile mode. ## Escalation SEV2 while oversell is active (customer-facing). Notify growth and support leads. | I16: https://github.com/mahesh-ai-architect/Second-Responder/blob/main/runbooks/RB-011-inventory-stock-sync.md | J16: Engineer should verify service relevance, conditions, and required steps. Add RB-009 to expected sources if detailed pool remediation is requested across runbooks.
... A22: T017 | B22: Development | C22: Conditional | D22: payments-api | E22: payments-api has 503s with no healthy upstream. Does that symptom alone prove pool saturation and require RB-009 remediation? | F22: Answered | G22: RB-001 | H22: No. RB-001 identifies connection pool OR target pod problems for this symptom. Check the pool; following RB-009 for remediation is conditioned on pool saturation. Do not assert a confirmed diagnosis. | I22: https://github.com/mahesh-ai-architect/Second-Responder/blob/main/runbooks/RB-001-payments-api-5xx.md | J22: Reviewer-authored starter expectation. Verify against source snapshots before using as a reference.
A23: T018 | B23: Development | C23: Unsupported | D23: outside corpus | E23: Give me the exact GPU reset command for a video-transcoding service whose workers have stopped. | F23: Clarification or abstention | H23: No video-transcoding runbook is in this corpus. Ask for the relevant runbook or service details; do not invent reset commands. | J23: Reviewer-authored starter expectation. Verify against source snapshots before using as a reference.
A24: T019 | B24: Development | C24: Unsupported | D24: outside corpus | E24: What command should I run to repair a Kafka controller quorum failure? | F24: Clarification or abstention | H24: No Kafka controller repair procedure is in this corpus. State the evidence limitation or ask for the relevant runbook; do not invent commands. | J24: Reviewer-authored starter expectation. Verify against source snapshots before using as a reference.
A25: T020 | B25: Development | C25: Ambiguous | D25: unknown | E25: It is failing. What should I restart? | F25: Clarification or abstention | H25: Ask for the affected service and exact alert or symptoms. Do not recommend an arbitrary restart. | J25: Reviewer-authored starter expectation. Verify against source snapshots before using as a reference.

Sheet Responses
A1: Responses | Paste actual n8n evidence and answer
A2: 20 Run IDs and Test IDs are prepared. No scores are fabricated. Fill the answer, evidence, outcome, appropriateness, reviewer, and claim inventory confirmation; grade atomic claims in Claim Review.
A5: Run ID | B5: Test ID | C5: Split | D5: Question | E5: Run timestamp | F5: Model | G5: Prompt / workflow version | H5: Corpus version / namespace | I5: Retrieved evidence (full text) | J5: Answer (JSON or text) | K5: Outcome | L5: Response appropriate? | M5: Citation errors | N5: Critical errors | O5: Total claims | P5: Supported claims | Q5: Unreviewed claims | R5: Faithfulness | S5: Review status | T5: Reviewer | U5: Notes | V5: Expected runbooks | W5: Expected behavior | X5: Claim inventory complete?
A6: R001 | B6: T001 | C6: =IF(B6="","",IFERROR(VLOOKUP(B6,'Test Cases'!$A$6:$J$205,2,FALSE),"Unknown Test ID")) -> Development | D6: =IF(B6="","",IFERROR(VLOOKUP(B6,'Test Cases'!$A$6:$J$205,5,FALSE),"Unknown Test ID")) -> payments-api /charge returns 5xx errors and Stripe requests time out. What should I check, what conditional remediation applies, and when should I escalate? | M6: =IF(A6="","",COUNTIFS('Claim Review'!$A$6:$A$2005,A6,'Claim Review'!$C$6:$C$2005,"<>",'Claim Review'!$G$6:$G$2005,"Wrong citation")+COUNTIFS('Claim Review'!$A$6:$A$2005,A6,'Claim Review'!$C$6:$C$2005,"<>",'Claim Review'!$G$6:$G$2005,"Missing citation")) -> 0 | N6: =IF(A6="","",COUNTIFS('Claim Review'!$A$6:$A$2005,A6,'Claim Review'!$C$6:$C$2005,"<>",'Claim Review'!$H$6:$H$2005,"Yes")) -> 0 | O6: =IF(A6="","",COUNTIFS('Claim Review'!$A$6:$A$2005,A6,'Claim Review'!$C$6:$C$2005,"<>")) -> 0 | P6: =IF(A6="","",COUNTIFS('Claim Review'!$A$6:$A$2005,A6,'Claim Review'!$C$6:$C$2005,"<>",'Claim Review'!$F$6:$F$2005,"Supported")) -> 0 | Q6: =IF(A6="","",O6-COUNTIFS('Claim Review'!$A$6:$A$2005,A6,'Claim Review'!$C$6:$C$2005,"<>",'Claim Review'!$K$6:$K$2005,"Yes")) -> 0 | R6: =IF(AND(A6<>"",COUNTIF($A$6:$A$205,A6)=1,COUNTIF('Test Cases'!$A$6:$A$205,B6)=1,I6<>"",J6<>"",OR(K6="Answered",K6="Clarification",K6="Abstained"),X6="Yes",T6<>"",O6>0,Q6=0),P6/MAX(1,O6),"") | S6: =IF(A6="","",IF(AND(J6="",K6=""),"Pending",IF(COUNTIF($A$6:$A$205,A6)<>1,"Duplicate Run ID",IF(COUNTIF('Test Cases'!$A$6:$A$205,B6)<>1,"Check Test ID",IF(K6="Error","FAIL",IF(OR(I6="",J6=""),"Needs evidence / answer",IF(NOT(OR(K6="Answered",K6="Clarification",K6="Abstained")),"Choose outcome",IF(X6<>"Yes","Confirm claim inventory",IF(AND(K6="Answered",O6=0),"Needs claims",IF(Q6>0,"Needs claim review",IF(OR(NOT(OR(L6="Yes",L6="No")),T6=""),"Needs response review",IF(OR(L6="No",M6>0,N6>0,AND(ISNUMBER(R6),R6<Dashboard!$B$5)),"FAIL","PASS")))))))))))) -> Pending | V6: =IF(B6="","",IFERROR(VLOOKUP(B6,'Test Cases'!$A$6:$J$205,7,FALSE),"Unknown Test ID")) -> RB-001 | W6: =IF(B6="","",IFERROR(VLOOKUP(B6,'Test Cases'!$A$6:$J$205,8,FALSE),"Unknown Test ID")) -> **Service:** payments-api | **Owner:** payments team | **Typical severity:** SEV2 (SEV1 if >50% of charges failing) ## Symptoms - Alert: "payments-api 5xx rate above 5% for 5 minutes" - Logs show "502 upstream prematurely closed connection" and "stripe request timeout after 3000ms" - Checkout failures rise in proportion to the error rate ## First checks 1. `kubectl rollout status deploy/payments-api -n prod` and `kubectl get pods -n prod -l app=payments-api` 2. Was there a deploy in the last 30 minutes? Check the deploy feed first. 3. Check status.stripe.com for an active Stripe incident. 4. Look at the orders DB connection pool (see RB-009 if saturated). ## Diagnosis - Errors started within 10 minutes of a deploy: assume bad release until proven otherwise. - Only /charge failing and Stripe status degraded: downstream provider issue, not us. - 503s with "no healthy upstream": connection pool or target pod problem. ## Remediation 1. Bad deploy: `kubectl rollout undo deploy/payments-api -n prod` 2. Stripe degraded: enable queued-charge mode (`payments.queue_mode=true`) so charges retry asynchronously instead of failing at checkout. 3. Pool saturation: follow RB-009. ## Escalation Escalate to the payments on-call lead if the error rate is above 20% or not resolved within 15 minutes. Declare SEV1 if more than 50% of charges are failing. ## After resolution Confirm the error rate stays below 0.5% for 15 minutes before closing the incident.
A7: R002 | B7: T002 | C7: =IF(B7="","",IFERROR(VLOOKUP(B7,'Test Cases'!$A$6:$J$205,2,FALSE),"Unknown Test ID")) -> Development | D7: =IF(B7="","",IFERROR(VLOOKUP(B7,'Test Cases'!$A$6:$J$205,5,FALSE),"Unknown Test ID")) -> The webhooks-inbound queue is above 10,000 and rising, with delivery failures going to the DLQ. What should I check, how should I recover, and when should I escalate? | M7: =IF(A7="","",COUNTIFS('Claim Review'!$A$6:$A$2005,A7,'Claim Review'!$C$6:$C$2005,"<>",'Claim Review'!$G$6:$G$2005,"Wrong citation")+COUNTIFS('Claim Review'!$A$6:$A$2005,A7,'Claim Review'!$C$6:$C$2005,"<>",'Claim Review'!$G$6:$G$2005,"Missing citation")) -> 0 | N7: =IF(A7="","",COUNTIFS('Claim Review'!$A$6:$A$2005,A7,'Claim Review'!$C$6:$C$2005,"<>",'Claim Review'!$H$6:$H$2005,"Yes")) -> 0 | O7: =IF(A7="","",COUNTIFS('Claim Review'!$A$6:$A$2005,A7,'Claim Review'!$C$6:$C$2005,"<>")) -> 0 | P7: =IF(A7="","",COUNTIFS('Claim Review'!$A$6:$A$2005,A7,'Claim Review'!$C$6:$C$2005,"<>",'Claim Review'!$F$6:$F$2005,"Supported")) -> 0 | Q7: =IF(A7="","",O7-COUNTIFS('Claim Review'!$A$6:$A$2005,A7,'Claim Review'!$C$6:$C$2005,"<>",'Claim Review'!$K$6:$K$2005,"Yes")) -> 0 | R7: =IF(AND(A7<>"",COUNTIF($A$6:$A$205,A7)=1,COUNTIF('Test Cases'!$A$6:$A$205,B7)=1,I7<>"",J7<>"",OR(K7="Answered",K7="Clarification",K7="Abstained"),X7="Yes",T7<>"",O7>0,Q7=0),P7/MAX(1,O7),"") | S7: =IF(A7="","",IF(AND(J7="",K7=""),"Pending",IF(COUNTIF($A$6:$A$205,A7)<>1,"Duplicate Run ID",IF(COUNTIF('Test Cases'!$A$6:$A$205,B7)<>1,"Check Test ID",IF(K7="Error","FAIL",IF(OR(I7="",J7=""),"Needs evidence / answer",IF(NOT(OR(K7="Answered",K7="Clarification",K7="Abstained")),"Choose outcome",IF(X7<>"Yes","Confirm claim inventory",IF(AND(K7="Answered",O7=0),"Needs claims",IF(Q7>0,"Needs claim review",IF(OR(NOT(OR(L7="Yes",L7="No")),T7=""),"Needs response review",IF(OR(L7="No",M7>0,N7>0,AND(ISNUMBER(R7),R7<Dashboard!$B$5)),"FAIL","PASS")))))))))))) -> Pending | V7: =IF(B7="","",IFERROR(VLOOKUP(B7,'Test Cases'!$A$6:$J$205,7,FALSE),"Unknown Test ID")) -> RB-002 | W7: =IF(B7="","",IFERROR(VLOOKUP(B7,'Test Cases'!$A$6:$J$205,8,FALSE),"Unknown Test ID")) -> **Service:** payments-api | **Owner:** payments team | **Typical severity:** SEV3 (SEV2 if backlog > 50,000) ## Symptoms - Queue "webhooks-inbound" depth above 10,000 and rising - Consumer lag growing; downstream order and inventory states go stale - Logs show "delivery attempt 8 failed, moving to DLQ" ## First checks 1. `kubectl get pods -n prod -l app=webhook-consumer` - look for CrashLoopBackOff 2. Check whether the same message_id is stuck at the head of the queue (poison message) 3. Check the downstream endpoint's own error rate ## Diagnosis - Consumer crash-looping: usually a bad deploy or a config change. - One message retried forever: poison message blocking the partition. - Downstream endpoint returning 500s: fix the downstream service first, not the consumer. ## Remediation 1. Fix or roll back the consumer deploy. 2. Move the poison message to the DLQ manually, note its message_id in the incident timeline. 3. Scale consumers: `kubectl scale deploy/webhook-consumer -n prod --replicas=6` 4. Replay the DLQ only after the root cause is fixed. Webhook handlers are idempotent on event_id - verify the consumer checks event_id before replaying. ## Escalation SEV2 if the backlog exceeds 50,000 or customer-visible order states are wrong.
A8: R003 | B8: T003 | C8: =IF(B8="","",IFERROR(VLOOKUP(B8,'Test Cases'!$A$6:$J$205,2,FALSE),"Unknown Test ID")) -> Development | D8: =IF(B8="","",IFERROR(VLOOKUP(B8,'Test Cases'!$A$6:$J$205,5,FALSE),"Unknown Test ID")) -> SSO login success is below 90%, with SAML signature validation failures. What should I check, what remediation applies, and when should I escalate? | M8: =IF(A8="","",COUNTIFS('Claim Review'!$A$6:$A$2005,A8,'Claim Review'!$C$6:$C$2005,"<>",'Claim Review'!$G$6:$G$2005,"Wrong citation")+COUNTIFS('Claim Review'!$A$6:$A$2005,A8,'Claim Review'!$C$6:$C$2005,"<>",'Claim Review'!$G$6:$G$2005,"Missing citation")) -> 0 | N8: =IF(A8="","",COUNTIFS('Claim Review'!$A$6:$A$2005,A8,'Claim Review'!$C$6:$C$2005,"<>",'Claim Review'!$H$6:$H$2005,"Yes")) -> 0 | O8: =IF(A8="","",COUNTIFS('Claim Review'!$A$6:$A$2005,A8,'Claim Review'!$C$6:$C$2005,"<>")) -> 0 | P8: =IF(A8="","",COUNTIFS('Claim Review'!$A$6:$A$2005,A8,'Claim Review'!$C$6:$C$2005,"<>",'Claim Review'!$F$6:$F$2005,"Supported")) -> 0 | Q8: =IF(A8="","",O8-COUNTIFS('Claim Review'!$A$6:$A$2005,A8,'Claim Review'!$C$6:$C$2005,"<>",'Claim Review'!$K$6:$K$2005,"Yes")) -> 0 | R8: =IF(AND(A8<>"",COUNTIF($A$6:$A$205,A8)=1,COUNTIF('Test Cases'!$A$6:$A$205,B8)=1,I8<>"",J8<>"",OR(K8="Answered",K8="Clarification",K8="Abstained"),X8="Yes",T8<>"",O8>0,Q8=0),P8/MAX(1,O8),"") | S8: =IF(A8="","",IF(AND(J8="",K8=""),"Pending",IF(COUNTIF($A$6:$A$205,A8)<>1,"Duplicate Run ID",IF(COUNTIF('Test Cases'!$A$6:$A$205,B8)<>1,"Check Test ID",IF(K8="Error","FAIL",IF(OR(I8="",J8=""),"Needs evidence / answer",IF(NOT(OR(K8="Answered",K8="Clarification",K8="Abstained")),"Choose outcome",IF(X8<>"Yes","Confirm claim inventory",IF(AND(K8="Answered",O8=0),"Needs claims",IF(Q8>0,"Needs claim review",IF(OR(NOT(OR(L8="Yes",L8="No")),T8=""),"Needs response review",IF(OR(L8="No",M8>0,N8>0,AND(ISNUMBER(R8),R8<Dashboard!$B$5)),"FAIL","PASS")))))))))))) -> Pending | V8: =IF(B8="","",IFERROR(VLOOKUP(B8,'Test Cases'!$A$6:$J$205,7,FALSE),"Unknown Test ID")) -> RB-003 | W8: =IF(B8="","",IFERROR(VLOOKUP(B8,'Test Cases'!$A$6:$J$205,8,FALSE),"Unknown Test ID")) -> **Service:** auth-service | **Owner:** identity team | **Typical severity:** SEV1 if all SSO logins fail ## Symptoms - Login success rate below 90% - Errors: "SAML signature validation failed" and "OIDC discovery document fetch failed" ## First checks 1. Fetch the IdP discovery document: `curl https://idp.example.com/.well-known/openid-configuration` 2. Compare the IdP signing certificate fingerprint against the configured metadata. 3. Check node clock drift: `chronyc tracking` - drift above 30 seconds breaks token validation. ## Diagnosis - Most common cause: the IdP rotated its signing certificate and our cached metadata is stale. - Discovery fetch failing: IdP outage or a network/DNS change on our side. - Signature failures plus clock drift: fix NTP before touching metadata. ## Remediation 1. Refresh IdP metadata from the admin console: Identity Providers -> Reload metadata. 2. Clear cached keys: `kubectl rollout restart deploy/auth-service -n prod` 3. If the IdP is down, post the status page notice and wait - do not bypass signature checks. ## Escalation SEV1 if all SSO logins are failing (workforce lockout). Page the identity on-call lead immediately.
A9: R004 | B9: T004 | C9: =IF(B9="","",IFERROR(VLOOKUP(B9,'Test Cases'!$A$6:$J$205,2,FALSE),"Unknown Test ID")) -> Development | D9: =IF(B9="","",IFERROR(VLOOKUP(B9,'Test Cases'!$A$6:$J$205,5,FALSE),"Unknown Test ID")) -> Users are not receiving MFA push prompts and approval latency exceeds 60 seconds. What should I check, what workaround applies, and when should I escalate? | M9: =IF(A9="","",COUNTIFS('Claim Review'!$A$6:$A$2005,A9,'Claim Review'!$C$6:$C$2005,"<>",'Claim Review'!$G$6:$G$2005,"Wrong citation")+COUNTIFS('Claim Review'!$A$6:$A$2005,A9,'Claim Review'!$C$6:$C$2005,"<>",'Claim Review'!$G$6:$G$2005,"Missing citation")) -> 0 | N9: =IF(A9="","",COUNTIFS('Claim Review'!$A$6:$A$2005,A9,'Claim Review'!$C$6:$C$2005,"<>",'Claim Review'!$H$6:$H$2005,"Yes")) -> 0 | O9: =IF(A9="","",COUNTIFS('Claim Review'!$A$6:$A$2005,A9,'Claim Review'!$C$6:$C$2005,"<>")) -> 0 | P9: =IF(A9="","",COUNTIFS('Claim Review'!$A$6:$A$2005,A9,'Claim Review'!$C$6:$C$2005,"<>",'Claim Review'!$F$6:$F$2005,"Supported")) -> 0 | Q9: =IF(A9="","",O9-COUNTIFS('Claim Review'!$A$6:$A$2005,A9,'Claim Review'!$C$6:$C$2005,"<>",'Claim Review'!$K$6:$K$2005,"Yes")) -> 0 | R9: =IF(AND(A9<>"",COUNTIF($A$6:$A$205,A9)=1,COUNTIF('Test Cases'!$A$6:$A$205,B9)=1,I9<>"",J9<>"",OR(K9="Answered",K9="Clarification",K9="Abstained"),X9="Yes",T9<>"",O9>0,Q9=0),P9/MAX(1,O9),"") | S9: =IF(A9="","",IF(AND(J9="",K9=""),"Pending",IF(COUNTIF($A$6:$A$205,A9)<>1,"Duplicate Run ID",IF(COUNTIF('Test Cases'!$A$6:$A$205,B9)<>1,"Check Test ID",IF(K9="Error","FAIL",IF(OR(I9="",J9=""),"Needs evidence / answer",IF(NOT(OR(K9="Answered",K9="Clarification",K9="Abstained")),"Choose outcome",IF(X9<>"Yes","Confirm claim inventory",IF(AND(K9="Answered",O9=0),"Needs claims",IF(Q9>0,"Needs claim review",IF(OR(NOT(OR(L9="Yes",L9="No")),T9=""),"Needs response review",IF(OR(L9="No",M9>0,N9>0,AND(ISNUMBER(R9),R9<Dashboard!$B$5)),"FAIL","PASS")))))))))))) -> Pending | V9: =IF(B9="","",IFERROR(VLOOKUP(B9,'Test Cases'!$A$6:$J$205,7,FALSE),"Unknown Test ID")) -> RB-004 | W9: =IF(B9="","",IFERROR(VLOOKUP(B9,'Test Cases'!$A$6:$J$205,8,FALSE),"Unknown Test ID")) -> **Service:** auth-service | **Owner:** identity team | **Typical severity:** SEV3 (SEV2 if >30 minutes) ## Symptoms - Push approval latency above 60 seconds, or failures with "push token revoked" - Users report not receiving MFA prompts ## First checks 1. Check the push vendor status page (APNs/FCM relay provider). 2. Token revocation rate split by platform: iOS vs Android. 3. Confirm TOTP (authenticator app) logins are unaffected. ## Diagnosis - One platform only: platform gateway or vendor-side issue. - Both platforms: our notification service or vendor account throttling. ## Remediation 1. Advise users to fall back to authenticator app (TOTP) codes - use the comms template in the incident channel. 2. If single-platform, open a vendor ticket with sample device tokens and timestamps. 3. Never disable or weaken MFA to "fix" delivery problems. ## Escalation Identity lead plus a vendor P1 ticket if degradation lasts more than 30 minutes or blocks a SEV1/SEV2 response.
A10: R005 | B10: T005 | C10: =IF(B10="","",IFERROR(VLOOKUP(B10,'Test Cases'!$A$6:$J$205,2,FALSE),"Unknown Test ID")) -> Development | D10: =IF(B10="","",IFERROR(VLOOKUP(B10,'Test Cases'!$A$6:$J$205,5,FALSE),"Unknown Test ID")) -> The indexer-nightly job is stalled and logs show mapper_parsing_exception. What should I check, how should I recover, and when should I escalate? | M10: =IF(A10="","",COUNTIFS('Claim Review'!$A$6:$A$2005,A10,'Claim Review'!$C$6:$C$2005,"<>",'Claim Review'!$G$6:$G$2005,"Wrong citation")+COUNTIFS('Claim Review'!$A$6:$A$2005,A10,'Claim Review'!$C$6:$C$2005,"<>",'Claim Review'!$G$6:$G$2005,"Missing citation")) -> 0 | N10: =IF(A10="","",COUNTIFS('Claim Review'!$A$6:$A$2005,A10,'Claim Review'!$C$6:$C$2005,"<>",'Claim Review'!$H$6:$H$2005,"Yes")) -> 0 | O10: =IF(A10="","",COUNTIFS('Claim Review'!$A$6:$A$2005,A10,'Claim Review'!$C$6:$C$2005,"<>")) -> 0 | P10: =IF(A10="","",COUNTIFS('Claim Review'!$A$6:$A$2005,A10,'Claim Review'!$C$6:$C$2005,"<>",'Claim Review'!$F$6:$F$2005,"Supported")) -> 0 | Q10: =IF(A10="","",O10-COUNTIFS('Claim Review'!$A$6:$A$2005,A10,'Claim Review'!$C$6:$C$2005,"<>",'Claim Review'!$K$6:$K$2005,"Yes")) -> 0 | R10: =IF(AND(A10<>"",COUNTIF($A$6:$A$205,A10)=1,COUNTIF('Test Cases'!$A$6:$A$205,B10)=1,I10<>"",J10<>"",OR(K10="Answered",K10="Clarification",K10="Abstained"),X10="Yes",T10<>"",O10>0,Q10=0),P10/MAX(1,O10),"") | S10: =IF(A10="","",IF(AND(J10="",K10=""),"Pending",IF(COUNTIF($A$6:$A$205,A10)<>1,"Duplicate Run ID",IF(COUNTIF('Test Cases'!$A$6:$A$205,B10)<>1,"Check Test ID",IF(K10="Error","FAIL",IF(OR(I10="",J10=""),"Needs evidence / answer",IF(NOT(OR(K10="Answered",K10="Clarification",K10="Abstained")),"Choose outcome",IF(X10<>"Yes","Confirm claim inventory",IF(AND(K10="Answered",O10=0),"Needs claims",IF(Q10>0,"Needs claim review",IF(OR(NOT(OR(L10="Yes",L10="No")),T10=""),"Needs response review",IF(OR(L10="No",M10>0,N10>0,AND(ISNUMBER(R10),R10<Dashboard!$B$5)),"FAIL","PASS")))))))))))) -> Pending | V10: =IF(B10="","",IFERROR(VLOOKUP(B10,'Test Cases'!$A$6:$J$205,7,FALSE),"Unknown Test ID")) -> RB-005 | W10: =IF(B10="","",IFERROR(VLOOKUP(B10,'Test Cases'!$A$6:$J$205,8,FALSE),"Unknown Test ID")) -> **Service:** search | **Owner:** platform team | **Typical severity:** SEV3 (SEV2 if customer-facing results stale > 2 hours) ## Symptoms - Nightly job "indexer-nightly" stuck, shard progress frozen - Error "mapper_parsing_exception" in indexer logs, or a data node above 85% disk ## First checks 1. Disk usage per data node; indexing halts at the high watermark. 2. Indexer logs for "mapper_parsing_exception" - a field arrived with a conflicting type. 3. GC pause times on data nodes. ## Diagnosis - Disk above watermark: snapshots or old indices consuming space. - Mapping exception: a producer started sending a field with a new type. - Progress frozen with healthy disk: long GC or a hung shard task. ## Remediation 1. Delete snapshots beyond retention; delete closed indices older than 90 days. 2. Fix the mapping for the offending field, or route that field to a quarantine index. 3. Resume the job from its checkpoint: `indexer-nightly --resume-from-shard` 4. If users also report worse results, check the last search deploy for analyzer changes before blaming the index. ## Escalation Platform on-call lead if customer-facing search results are stale for more than 2 hours.
A11: R006 | B11: T006 | C11: =IF(B11="","",IFERROR(VLOOKUP(B11,'Test Cases'!$A$6:$J$205,2,FALSE),"Unknown Test ID")) -> Development | D11: =IF(B11="","",IFERROR(VLOOKUP(B11,'Test Cases'!$A$6:$J$205,5,FALSE),"Unknown Test ID")) -> Checkout p99 is above 2.5 seconds after a deploy and promo validation dominates traces. What should I check, what remediation applies, and how should I verify recovery? | M11: =IF(A11="","",COUNTIFS('Claim Review'!$A$6:$A$2005,A11,'Claim Review'!$C$6:$C$2005,"<>",'Claim Review'!$G$6:$G$2005,"Wrong citation")+COUNTIFS('Claim Review'!$A$6:$A$2005,A11,'Claim Review'!$C$6:$C$2005,"<>",'Claim Review'!$G$6:$G$2005,"Missing citation")) -> 0 | N11: =IF(A11="","",COUNTIFS('Claim Review'!$A$6:$A$2005,A11,'Claim Review'!$C$6:$C$2005,"<>",'Claim Review'!$H$6:$H$2005,"Yes")) -> 0 | O11: =IF(A11="","",COUNTIFS('Claim Review'!$A$6:$A$2005,A11,'Claim Review'!$C$6:$C$2005,"<>")) -> 0 | P11: =IF(A11="","",COUNTIFS('Claim Review'!$A$6:$A$2005,A11,'Claim Review'!$C$6:$C$2005,"<>",'Claim Review'!$F$6:$F$2005,"Supported")) -> 0 | Q11: =IF(A11="","",O11-COUNTIFS('Claim Review'!$A$6:$A$2005,A11,'Claim Review'!$C$6:$C$2005,"<>",'Claim Review'!$K$6:$K$2005,"Yes")) -> 0 | R11: =IF(AND(A11<>"",COUNTIF($A$6:$A$205,A11)=1,COUNTIF('Test Cases'!$A$6:$A$205,B11)=1,I11<>"",J11<>"",OR(K11="Answered",K11="Clarification",K11="Abstained"),X11="Yes",T11<>"",O11>0,Q11=0),P11/MAX(1,O11),"") | S11: =IF(A11="","",IF(AND(J11="",K11=""),"Pending",IF(COUNTIF($A$6:$A$205,A11)<>1,"Duplicate Run ID",IF(COUNTIF('Test Cases'!$A$6:$A$205,B11)<>1,"Check Test ID",IF(K11="Error","FAIL",IF(OR(I11="",J11=""),"Needs evidence / answer",IF(NOT(OR(K11="Answered",K11="Clarification",K11="Abstained")),"Choose outcome",IF(X11<>"Yes","Confirm claim inventory",IF(AND(K11="Answered",O11=0),"Needs claims",IF(Q11>0,"Needs claim review",IF(OR(NOT(OR(L11="Yes",L11="No")),T11=""),"Needs response review",IF(OR(L11="No",M11>0,N11>0,AND(ISNUMBER(R11),R11<Dashboard!$B$5)),"FAIL","PASS")))))))))))) -> Pending | V11: =IF(B11="","",IFERROR(VLOOKUP(B11,'Test Cases'!$A$6:$J$205,7,FALSE),"Unknown Test ID")) -> RB-006 | W11: =IF(B11="","",IFERROR(VLOOKUP(B11,'Test Cases'!$A$6:$J$205,8,FALSE),"Unknown Test ID")) -> **Service:** checkout | **Owner:** growth team | **Typical severity:** SEV2 if conversion impact confirmed ## Symptoms - Checkout p99 latency above 2.5s against a 900ms baseline - APM traces show time concentrated in promo validation or the inventory call ## First checks 1. APM waterfall for a slow trace: which span eats the time? 2. Was "checkout_v2" enabled in the last deploy? 3. Check for N+1 query patterns in cart service database calls. ## Diagnosis - Promo validation called synchronously per cart item: known regression pattern from the v2 flag. - Cache bypass header set by the new frontend build: every request hits origin services. - DB time dominant: hand off to RB-009. ## Remediation 1. Disable the flag: `checkout_v2=false` - instant rollback, no deploy needed. 2. Enable async promo validation: `promo.async_validation=true` 3. Verify p99 below 1.2s for 10 minutes before closing. ## Escalation Growth team lead. SEV2 if analytics confirms a conversion drop.
A12: R007 | B12: T007 | C12: =IF(B12="","",IFERROR(VLOOKUP(B12,'Test Cases'!$A$6:$J$205,2,FALSE),"Unknown Test ID")) -> Development | D12: =IF(B12="","",IFERROR(VLOOKUP(B12,'Test Cases'!$A$6:$J$205,5,FALSE),"Unknown Test ID")) -> Email queues are backing up and the provider returns 429 provider rate limit exceeded. What should I check, what remediation applies, and when should I escalate? | M12: =IF(A12="","",COUNTIFS('Claim Review'!$A$6:$A$2005,A12,'Claim Review'!$C$6:$C$2005,"<>",'Claim Review'!$G$6:$G$2005,"Wrong citation")+COUNTIFS('Claim Review'!$A$6:$A$2005,A12,'Claim Review'!$C$6:$C$2005,"<>",'Claim Review'!$G$6:$G$2005,"Missing citation")) -> 0 | N12: =IF(A12="","",COUNTIFS('Claim Review'!$A$6:$A$2005,A12,'Claim Review'!$C$6:$C$2005,"<>",'Claim Review'!$H$6:$H$2005,"Yes")) -> 0 | O12: =IF(A12="","",COUNTIFS('Claim Review'!$A$6:$A$2005,A12,'Claim Review'!$C$6:$C$2005,"<>")) -> 0 | P12: =IF(A12="","",COUNTIFS('Claim Review'!$A$6:$A$2005,A12,'Claim Review'!$C$6:$C$2005,"<>",'Claim Review'!$F$6:$F$2005,"Supported")) -> 0 | Q12: =IF(A12="","",O12-COUNTIFS('Claim Review'!$A$6:$A$2005,A12,'Claim Review'!$C$6:$C$2005,"<>",'Claim Review'!$K$6:$K$2005,"Yes")) -> 0 | R12: =IF(AND(A12<>"",COUNTIF($A$6:$A$205,A12)=1,COUNTIF('Test Cases'!$A$6:$A$205,B12)=1,I12<>"",J12<>"",OR(K12="Answered",K12="Clarification",K12="Abstained"),X12="Yes",T12<>"",O12>0,Q12=0),P12/MAX(1,O12),"") | S12: =IF(A12="","",IF(AND(J12="",K12=""),"Pending",IF(COUNTIF($A$6:$A$205,A12)<>1,"Duplicate Run ID",IF(COUNTIF('Test Cases'!$A$6:$A$205,B12)<>1,"Check Test ID",IF(K12="Error","FAIL",IF(OR(I12="",J12=""),"Needs evidence / answer",IF(NOT(OR(K12="Answered",K12="Clarification",K12="Abstained")),"Choose outcome",IF(X12<>"Yes","Confirm claim inventory",IF(AND(K12="Answered",O12=0),"Needs claims",IF(Q12>0,"Needs claim review",IF(OR(NOT(OR(L12="Yes",L12="No")),T12=""),"Needs response review",IF(OR(L12="No",M12>0,N12>0,AND(ISNUMBER(R12),R12<Dashboard!$B$5)),"FAIL","PASS")))))))))))) -> Pending | V12: =IF(B12="","",IFERROR(VLOOKUP(B12,'Test Cases'!$A$6:$J$205,7,FALSE),"Unknown Test ID")) -> RB-007 | W12: =IF(B12="","",IFERROR(VLOOKUP(B12,'Test Cases'!$A$6:$J$205,8,FALSE),"Unknown Test ID")) -> **Service:** notifications | **Owner:** platform team | **Typical severity:** SEV3 (SEV2 if OTP/password-reset mail delayed > 15 min) ## Symptoms - Email queue depth rising, send latency above 10 minutes - Provider returns "429 provider rate limit exceeded" ## First checks 1. Split queue depth: transactional vs marketing. A campaign burst sharing the queue is the usual cause. 2. Worker replica count vs the autoscaling cap. 3. Provider rate limit status for our account. ## Diagnosis - Marketing burst: a campaign send flooded the shared queue. - Workers at cap with steady traffic: genuine capacity ceiling. - 429s at low volume: provider-side throttling or account limit change. ## Remediation 1. Prioritize the "notifications-transactional" queue - OTP and password resets go first. 2. Raise worker replicas up to the max of 20. 3. Pause campaign sends: `campaigns.paused=true` 4. Never drop transactional messages to clear a backlog. ## Escalation If password-reset or OTP mail is delayed more than 15 minutes this becomes auth-impacting - raise to SEV2 and cross-reference RB-004.
A13: R008 | B13: T008 | C13: =IF(B13="","",IFERROR(VLOOKUP(B13,'Test Cases'!$A$6:$J$205,2,FALSE),"Unknown Test ID")) -> Development | D13: =IF(B13="","",IFERROR(VLOOKUP(B13,'Test Cases'!$A$6:$J$205,5,FALSE),"Unknown Test ID")) -> Replica lag is above 30 seconds and climbing while a backfill runs. What should I check, what remediation conditions apply, and when should I escalate? | M13: =IF(A13="","",COUNTIFS('Claim Review'!$A$6:$A$2005,A13,'Claim Review'!$C$6:$C$2005,"<>",'Claim Review'!$G$6:$G$2005,"Wrong citation")+COUNTIFS('Claim Review'!$A$6:$A$2005,A13,'Claim Review'!$C$6:$C$2005,"<>",'Claim Review'!$G$6:$G$2005,"Missing citation")) -> 0 | N13: =IF(A13="","",COUNTIFS('Claim Review'!$A$6:$A$2005,A13,'Claim Review'!$C$6:$C$2005,"<>",'Claim Review'!$H$6:$H$2005,"Yes")) -> 0 | O13: =IF(A13="","",COUNTIFS('Claim Review'!$A$6:$A$2005,A13,'Claim Review'!$C$6:$C$2005,"<>")) -> 0 | P13: =IF(A13="","",COUNTIFS('Claim Review'!$A$6:$A$2005,A13,'Claim Review'!$C$6:$C$2005,"<>",'Claim Review'!$F$6:$F$2005,"Supported")) -> 0 | Q13: =IF(A13="","",O13-COUNTIFS('Claim Review'!$A$6:$A$2005,A13,'Claim Review'!$C$6:$C$2005,"<>",'Claim Review'!$K$6:$K$2005,"Yes")) -> 0 | R13: =IF(AND(A13<>"",COUNTIF($A$6:$A$205,A13)=1,COUNTIF('Test Cases'!$A$6:$A$205,B13)=1,I13<>"",J13<>"",OR(K13="Answered",K13="Clarification",K13="Abstained"),X13="Yes",T13<>"",O13>0,Q13=0),P13/MAX(1,O13),"") | S13: =IF(A13="","",IF(AND(J13="",K13=""),"Pending",IF(COUNTIF($A$6:$A$205,A13)<>1,"Duplicate Run ID",IF(COUNTIF('Test Cases'!$A$6:$A$205,B13)<>1,"Check Test ID",IF(K13="Error","FAIL",IF(OR(I13="",J13=""),"Needs evidence / answer",IF(NOT(OR(K13="Answered",K13="Clarification",K13="Abstained")),"Choose outcome",IF(X13<>"Yes","Confirm claim inventory",IF(AND(K13="Answered",O13=0),"Needs claims",IF(Q13>0,"Needs claim review",IF(OR(NOT(OR(L13="Yes",L13="No")),T13=""),"Needs response review",IF(OR(L13="No",M13>0,N13>0,AND(ISNUMBER(R13),R13<Dashboard!$B$5)),"FAIL","PASS")))))))))))) -> Pending | V13: =IF(B13="","",IFERROR(VLOOKUP(B13,'Test Cases'!$A$6:$J$205,7,FALSE),"Unknown Test ID")) -> RB-008 | W13: =IF(B13="","",IFERROR(VLOOKUP(B13,'Test Cases'!$A$6:$J$205,8,FALSE),"Unknown Test ID")) -> **Service:** database-primary | **Owner:** platform (DB) team | **Typical severity:** SEV2 (SEV1 if lag > 300s with unhealthy primary) ## Symptoms - Replica lag above 30 seconds and climbing in pg_stat_replication - Read-your-write complaints from application teams ## First checks 1. `SELECT pid, application_name, now() - xact_start AS xact_age FROM pg_stat_activity ORDER BY xact_age DESC;` 2. Identify bulk jobs by application_name - backfills are the usual blocker. 3. Replica disk I/O utilisation. ## Diagnosis - One long transaction on the primary: replica replay is blocked behind it. - Backfill job running during peak: contention, not failure. - Replica disk saturated: replay cannot keep up even with a healthy primary. ## Remediation 1. With incident commander approval, terminate the blocking backfill: `SELECT pg_terminate_backend(<pid>);` 2. Throttle or pause batch jobs until lag drains below 5 seconds. 3. Controlled failover only if the primary is genuinely failing AND lag is under 10 seconds. 4. Never promote a replica with lag above 300 seconds without data-loss sign-off from the DB lead. ## Escalation SEV1 if lag exceeds 300 seconds with an unhealthy primary. Page the DB lead.
A14: R009 | B14: T009 | C14: =IF(B14="","",IFERROR(VLOOKUP(B14,'Test Cases'!$A$6:$J$205,2,FALSE),"Unknown Test ID")) -> Development | D14: =IF(B14="","",IFERROR(VLOOKUP(B14,'Test Cases'!$A$6:$J$205,5,FALSE),"Unknown Test ID")) -> The orders database connection pool is saturated and requests are failing. What should I check first, what remediation should I follow, and when should I escalate? | M14: =IF(A14="","",COUNTIFS('Claim Review'!$A$6:$A$2005,A14,'Claim Review'!$C$6:$C$2005,"<>",'Claim Review'!$G$6:$G$2005,"Wrong citation")+COUNTIFS('Claim Review'!$A$6:$A$2005,A14,'Claim Review'!$C$6:$C$2005,"<>",'Claim Review'!$G$6:$G$2005,"Missing citation")) -> 0 | N14: =IF(A14="","",COUNTIFS('Claim Review'!$A$6:$A$2005,A14,'Claim Review'!$C$6:$C$2005,"<>",'Claim Review'!$H$6:$H$2005,"Yes")) -> 0 | O14: =IF(A14="","",COUNTIFS('Claim Review'!$A$6:$A$2005,A14,'Claim Review'!$C$6:$C$2005,"<>")) -> 0 | P14: =IF(A14="","",COUNTIFS('Claim Review'!$A$6:$A$2005,A14,'Claim Review'!$C$6:$C$2005,"<>",'Claim Review'!$F$6:$F$2005,"Supported")) -> 0 | Q14: =IF(A14="","",O14-COUNTIFS('Claim Review'!$A$6:$A$2005,A14,'Claim Review'!$C$6:$C$2005,"<>",'Claim Review'!$K$6:$K$2005,"Yes")) -> 0 | R14: =IF(AND(A14<>"",COUNTIF($A$6:$A$205,A14)=1,COUNTIF('Test Cases'!$A$6:$A$205,B14)=1,I14<>"",J14<>"",OR(K14="Answered",K14="Clarification",K14="Abstained"),X14="Yes",T14<>"",O14>0,Q14=0),P14/MAX(1,O14),"") | S14: =IF(A14="","",IF(AND(J14="",K14=""),"Pending",IF(COUNTIF($A$6:$A$205,A14)<>1,"Duplicate Run ID",IF(COUNTIF('Test Cases'!$A$6:$A$205,B14)<>1,"Check Test ID",IF(K14="Error","FAIL",IF(OR(I14="",J14=""),"Needs evidence / answer",IF(NOT(OR(K14="Answered",K14="Clarification",K14="Abstained")),"Choose outcome",IF(X14<>"Yes","Confirm claim inventory",IF(AND(K14="Answered",O14=0),"Needs claims",IF(Q14>0,"Needs claim review",IF(OR(NOT(OR(L14="Yes",L14="No")),T14=""),"Needs response review",IF(OR(L14="No",M14>0,N14>0,AND(ISNUMBER(R14),R14<Dashboard!$B$5)),"FAIL","PASS")))))))))))) -> Pending | V14: =IF(B14="","",IFERROR(VLOOKUP(B14,'Test Cases'!$A$6:$J$205,7,FALSE),"Unknown Test ID")) -> RB-009 | W14: =IF(B14="","",IFERROR(VLOOKUP(B14,'Test Cases'!$A$6:$J$205,8,FALSE),"Unknown Test ID")) -> **Service:** database-primary | **Owner:** platform (DB) team | **Typical severity:** SEV2 ## Symptoms - Application errors: "FATAL: remaining connection slots are reserved for non-replication superuser connections" - PgBouncer client wait queue growing ## First checks 1. `SELECT application_name, state, count(*) FROM pg_stat_activity GROUP BY 1, 2 ORDER BY 3 DESC;` 2. PgBouncer: `SHOW POOLS;` - look at cl_waiting. 3. Sessions stuck in "idle in transaction" point at a leaking deploy. ## Diagnosis - One application_name dominating with idle-in-transaction sessions: connection leak in a recent deploy. - All apps up evenly: genuine load growth or a batch job. - Pooler queue up but DB sessions low: pool size misconfigured after a deploy. ## Remediation 1. Restart the pooler to clear leaked sessions: `systemctl restart pgbouncer` 2. Roll back the leaking deploy; the leak, not the pool size, is the bug. 3. Temporary pool_size increase of 25% is allowed only if DB CPU is below 60%. ## Escalation DB lead if it recurs twice in 24 hours - that is a leak hunt, treat as SEV2.
A15: R010 | B15: T010 | C15: =IF(B15="","",IFERROR(VLOOKUP(B15,'Test Cases'!$A$6:$J$205,2,FALSE),"Unknown Test ID")) -> Development | D15: =IF(B15="","",IFERROR(VLOOKUP(B15,'Test Cases'!$A$6:$J$205,5,FALSE),"Unknown Test ID")) -> CDN cache hit ratio dropped below 70%, origin traffic tripled, and edge 503s appeared after a config push. What should I check and do? | M15: =IF(A15="","",COUNTIFS('Claim Review'!$A$6:$A$2005,A15,'Claim Review'!$C$6:$C$2005,"<>",'Claim Review'!$G$6:$G$2005,"Wrong citation")+COUNTIFS('Claim Review'!$A$6:$A$2005,A15,'Claim Review'!$C$6:$C$2005,"<>",'Claim Review'!$G$6:$G$2005,"Missing citation")) -> 0 | N15: =IF(A15="","",COUNTIFS('Claim Review'!$A$6:$A$2005,A15,'Claim Review'!$C$6:$C$2005,"<>",'Claim Review'!$H$6:$H$2005,"Yes")) -> 0 | O15: =IF(A15="","",COUNTIFS('Claim Review'!$A$6:$A$2005,A15,'Claim Review'!$C$6:$C$2005,"<>")) -> 0 | P15: =IF(A15="","",COUNTIFS('Claim Review'!$A$6:$A$2005,A15,'Claim Review'!$C$6:$C$2005,"<>",'Claim Review'!$F$6:$F$2005,"Supported")) -> 0 | Q15: =IF(A15="","",O15-COUNTIFS('Claim Review'!$A$6:$A$2005,A15,'Claim Review'!$C$6:$C$2005,"<>",'Claim Review'!$K$6:$K$2005,"Yes")) -> 0 | R15: =IF(AND(A15<>"",COUNTIF($A$6:$A$205,A15)=1,COUNTIF('Test Cases'!$A$6:$A$205,B15)=1,I15<>"",J15<>"",OR(K15="Answered",K15="Clarification",K15="Abstained"),X15="Yes",T15<>"",O15>0,Q15=0),P15/MAX(1,O15),"") | S15: =IF(A15="","",IF(AND(J15="",K15=""),"Pending",IF(COUNTIF($A$6:$A$205,A15)<>1,"Duplicate Run ID",IF(COUNTIF('Test Cases'!$A$6:$A$205,B15)<>1,"Check Test ID",IF(K15="Error","FAIL",IF(OR(I15="",J15=""),"Needs evidence / answer",IF(NOT(OR(K15="Answered",K15="Clarification",K15="Abstained")),"Choose outcome",IF(X15<>"Yes","Confirm claim inventory",IF(AND(K15="Answered",O15=0),"Needs claims",IF(Q15>0,"Needs claim review",IF(OR(NOT(OR(L15="Yes",L15="No")),T15=""),"Needs response review",IF(OR(L15="No",M15>0,N15>0,AND(ISNUMBER(R15),R15<Dashboard!$B$5)),"FAIL","PASS")))))))))))) -> Pending | V15: =IF(B15="","",IFERROR(VLOOKUP(B15,'Test Cases'!$A$6:$J$205,7,FALSE),"Unknown Test ID")) -> RB-010 | W15: =IF(B15="","",IFERROR(VLOOKUP(B15,'Test Cases'!$A$6:$J$205,8,FALSE),"Unknown Test ID")) -> **Service:** cdn-edge | **Owner:** platform team | **Typical severity:** SEV2 if origin is saturating ## Symptoms - Cache hit ratio below 70% against a 92% baseline - Origin traffic roughly 3x normal; scattered 503s by POP after a config push ## First checks 1. Hit ratio split by POP and by path - global or localized? 2. Was there a CDN config push or a full purge in the last hour? 3. Origin response codes and origin CPU. ## Diagnosis - Cache key changed to include the session cookie: every user becomes a unique cache entry. - Full purge during peak: self-inflicted origin stampede. - One POP only: bad config version on that POP or an origin shield misroute. ## Remediation 1. Roll back the CDN config to the previous known-good version. 2. Enable origin shield and request coalescing to protect the origin. 3. Re-warm the top 500 URLs after rollback. 4. Disable scheduled purges until the root cause is confirmed. ## Escalation SEV2 if the origin is saturating. Protect the origin first, investigate second.
